Workbook
Name TodayDate: Settings!$B$5
Name CurMonthStart: Settings!$B$6
Name CurMonthEnd: Settings!$B$7
Name LastMonthStart: Settings!$B$8
Name LastMonthEnd: Settings!$B$9
Name CurYearStart: Settings!$B$10
Name CurYearEnd: Settings!$B$11
Name List_YesNo: Settings!$A$25:$A$26
Name List_NeedWant: Settings!$B$25:$B$26
Name PaymentMethodList: Dim_PaymentMethod[MethodName]
Name CategoryNameList: Dim_Category[CategoryName]
Name ExpenseCategoryList: Dim_Category[CategoryName]
Name VendorNameList: Dim_Vendor[VendorName]
Name AccountNameList: Dim_Account[AccountName]
Name SourceNameList: Dim_Source[SourceName]
Name SignConvention: 'Bank Import'!$D$13

Sheet Dashboard
A1: Personal Finance Planner
A3: ="Data as of " & TEXT(TodayDate,"mmmm d, yyyy") & " | Refresh: Data > Refresh All, then Ctrl+Alt+F9 to recalculate"
A5: MONTHLY INCOME | E5: MONTHLY EXPENSES | I5: MONTHLY SAVINGS | M5: SAVINGS RATE %
A6: =SUMIFS(Fact_Income[NetAmount],Fact_Income[Date],">="&CurMonthStart,Fact_Income[Date],"<="&CurMonthEnd)+SUMIFS(BankImportRaw[AbsAmount],BankImportRaw[TransactionType],"Income",BankImportRaw[Date],">="&CurMonthStart,BankImportRaw[Date],"<="&CurMonthEnd) | E6: =SUMIFS(Fact_Expenses[Amount],Fact_Expenses[Date],">="&CurMonthStart,Fact_Expenses[Date],"<="&CurMonthEnd)+SUMIFS(BankImportRaw[AbsAmount],BankImportRaw[TransactionType],"Expense",BankImportRaw[Date],">="&CurMonthStart,BankImportRaw[Date],"<="&CurMonthEnd) | I6: =A6-E6 | M6: =IFERROR(I6/A6,0)
A10: NET CASH FLOW | E10: BUDGET UTILIZATION % | I10: EMERGENCY FUND | M10: TOTAL SAVED (ALL GOALS)
A11: =I6-SUMIFS(Fact_SavingsTransfers[Amount],Fact_SavingsTransfers[Date],">="&CurMonthStart,Fact_SavingsTransfers[Date],"<="&CurMonthEnd) | E11: =IFERROR(SUM(Budget[Actual])/SUM(Budget[MonthlyBudget]),0) | I11: =SUMIFS(Fact_SavingsTransfers[Amount],Fact_SavingsTransfers[GoalName],"Emergency Fund") | M11: =SUM(Dim_Goal[CurrentAmount])
A67: Widgets & Quick Insights
A69: Top Expenses (This Month, Expenses tab only) | E69: Largest Vendors (This Month) | H69: Largest Categories (This Month) | K69: Behavior Metrics
A70: Vendor | B70: Category | C70: Amount | E70: Vendor | F70: Amount | H70: Category | I70: Amount
A71: =IFERROR(INDEX(Fact_Expenses[VendorName],MATCH($C71,Fact_Expenses[CurMonthAmt],0)),"") | B71: =IFERROR(INDEX(Fact_Expenses[CategoryName],MATCH($C71,Fact_Expenses[CurMonthAmt],0)),"") | C71: =IFERROR(LARGE(Fact_Expenses[CurMonthAmt],1),0) | E71: =IFERROR(INDEX(Dim_Vendor[VendorName],MATCH($F71,Dim_Vendor[CurMonthSpend],0)),"") | F71: =IFERROR(LARGE(Dim_Vendor[CurMonthSpend],1),0) | H71: =IFERROR(INDEX(Budget[CategoryName],MATCH($I71,Budget[Actual],0)),"") | I71: =IFERROR(LARGE(Budget[Actual],1),0) | K71: Need vs Want % | M71: =IFERROR((SUMIFS(Fact_Expenses[Amount],Fact_Expenses[NeedWantFlag],"Need")+SUMIFS(BankImportRaw[AbsAmount],BankImportRaw[NeedWantFlag],"Need",BankImportRaw[TransactionType],"Expense"))/(SUM(Fact_Expenses[Amount])+SUMIFS(BankImportRaw[AbsAmount],BankImportRaw[TransactionType],"Expense")),0)
A72: =IFERROR(INDEX(Fact_Expenses[VendorName],MATCH($C72,Fact_Expenses[CurMonthAmt],0)),"") | B72: =IFERROR(INDEX(Fact_Expenses[CategoryName],MATCH($C72,Fact_Expenses[CurMonthAmt],0)),"") | C72: =IFERROR(LARGE(Fact_Expenses[CurMonthAmt],2),0) | E72: =IFERROR(INDEX(Dim_Vendor[VendorName],MATCH($F72,Dim_Vendor[CurMonthSpend],0)),"") | F72: =IFERROR(LARGE(Dim_Vendor[CurMonthSpend],2),0) | H72: =IFERROR(INDEX(Budget[CategoryName],MATCH($I72,Budget[Actual],0)),"") | I72: =IFERROR(LARGE(Budget[Actual],2),0) | K72: Recurring Spend / mo (manual entries only) | M72: =SUMIFS(Fact_Expenses[Amount],Fact_Expenses[RecurringFlag],"Yes",Fact_Expenses[Date],">="&CurMonthStart,Fact_Expenses[Date],"<="&CurMonthEnd)
A73: =IFERROR(INDEX(Fact_Expenses[VendorName],MATCH($C73,Fact_Expenses[CurMonthAmt],0)),"") | B73: =IFERROR(INDEX(Fact_Expenses[CategoryName],MATCH($C73,Fact_Expenses[CurMonthAmt],0)),"") | C73: =IFERROR(LARGE(Fact_Expenses[CurMonthAmt],3),0) | E73: =IFERROR(INDEX(Dim_Vendor[VendorName],MATCH($F73,Dim_Vendor[CurMonthSpend],0)),"") | F73: =IFERROR(LARGE(Dim_Vendor[CurMonthSpend],3),0) | H73: =IFERROR(INDEX(Budget[CategoryName],MATCH($I73,Budget[Actual],0)),"") | I73: =IFERROR(LARGE(Budget[Actual],3),0)
A74: =IFERROR(INDEX(Fact_Expenses[VendorName],MATCH($C74,Fact_Expenses[CurMonthAmt],0)),"") | B74: =IFERROR(INDEX(Fact_Expenses[CategoryName],MATCH($C74,Fact_Expenses[CurMonthAmt],0)),"") | C74: =IFERROR(LARGE(Fact_Expenses[CurMonthAmt],4),0) | E74: =IFERROR(INDEX(Dim_Vendor[VendorName],MATCH($F74,Dim_Vendor[CurMonthSpend],0)),"") | F74: =IFERROR(LARGE(Dim_Vendor[CurMonthSpend],4),0) | H74: =IFERROR(INDEX(Budget[CategoryName],MATCH($I74,Budget[Actual],0)),"") | I74: =IFERROR(LARGE(Budget[Actual],4),0)
A75: =IFERROR(INDEX(Fact_Expenses[VendorName],MATCH($C75,Fact_Expenses[CurMonthAmt],0)),"") | B75: =IFERROR(INDEX(Fact_Expenses[CategoryName],MATCH($C75,Fact_Expenses[CurMonthAmt],0)),"") | C75: =IFERROR(LARGE(Fact_Expenses[CurMonthAmt],5),0) | E75: =IFERROR(INDEX(Dim_Vendor[VendorName],MATCH($F75,Dim_Vendor[CurMonthSpend],0)),"") | F75: =IFERROR(LARGE(Dim_Vendor[CurMonthSpend],5),0) | H75: =IFERROR(INDEX(Budget[CategoryName],MATCH($I75,Budget[Actual],0)),"") | I75: =IFERROR(LARGE(Budget[Actual],5),0)
A78: Budget Status (red = over budget) | D78: Recent Transactions (Expenses tab only)
A79: Category | B79: Status | D79: Date | E79: Vendor | F79: Category | G79: Amount
A80: =Budget!A11 | B80: =Budget!F11 | D80: =IFERROR(INDEX(Fact_Expenses[Date],COUNTA(Fact_Expenses[ExpenseID])-0),"") | E80: =IFERROR(INDEX(Fact_Expenses[VendorName],COUNTA(Fact_Expenses[ExpenseID])-0),"") | F80: =IFERROR(INDEX(Fact_Expenses[CategoryName],COUNTA(Fact_Expenses[ExpenseID])-0),"") | G80: =IFERROR(INDEX(Fact_Expenses[Amount],COUNTA(Fact_Expenses[ExpenseID])-0),"")
A81: =Budget!A12 | B81: =Budget!F12 | D81: =IFERROR(INDEX(Fact_Expenses[Date],COUNTA(Fact_Expenses[ExpenseID])-1),"") | E81: =IFERROR(INDEX(Fact_Expenses[VendorName],COUNTA(Fact_Expenses[ExpenseID])-1),"") | F81: =IFERROR(INDEX(Fact_Expenses[CategoryName],COUNTA(Fact_Expenses[ExpenseID])-1),"") | G81: =IFERROR(INDEX(Fact_Expenses[Amount],COUNTA(Fact_Expenses[ExpenseID])-1),"")
A82: =Budget!A13 | B82: =Budget!F13 | D82: =IFERROR(INDEX(Fact_Expenses[Date],COUNTA(Fact_Expenses[ExpenseID])-2),"") | E82: =IFERROR(INDEX(Fact_Expenses[VendorName],COUNTA(Fact_Expenses[ExpenseID])-2),"") | F82: =IFERROR(INDEX(Fact_Expenses[CategoryName],COUNTA(Fact_Expenses[ExpenseID])-2),"") | G82: =IFERROR(INDEX(Fact_Expenses[Amount],COUNTA(Fact_Expenses[ExpenseID])-2),"")
A83: =Budget!A14 | B83: =Budget!F14 | D83: =IFERROR(INDEX(Fact_Expenses[Date],COUNTA(Fact_Expenses[ExpenseID])-3),"") | E83: =IFERROR(INDEX(Fact_Expenses[VendorName],COUNTA(Fact_Expenses[ExpenseID])-3),"") | F83: =IFERROR(INDEX(Fact_Expenses[CategoryName],COUNTA(Fact_Expenses[ExpenseID])-3),"") | G83: =IFERROR(INDEX(Fact_Expenses[Amount],COUNTA(Fact_Expenses[ExpenseID])-3),"")
A84: =Budget!A15 | B84: =Budget!F15 | D84: =IFERROR(INDEX(Fact_Expenses[Date],COUNTA(Fact_Expenses[ExpenseID])-4),"") | E84: =IFERROR(INDEX(Fact_Expenses[VendorName],COUNTA(Fact_Expenses[ExpenseID])-4),"") | F84: =IFERROR(INDEX(Fact_Expenses[CategoryName],COUNTA(Fact_Expenses[ExpenseID])-4),"") | G84: =IFERROR(INDEX(Fact_Expenses[Amount],COUNTA(Fact_Expenses[ExpenseID])-4),"")
A85: =Budget!A16 | B85: =Budget!F16 | D85: =IFERROR(INDEX(Fact_Expenses[Date],COUNTA(Fact_Expenses[ExpenseID])-5),"") | E85: =IFERROR(INDEX(Fact_Expenses[VendorName],COUNTA(Fact_Expenses[ExpenseID])-5),"") | F85: =IFERROR(INDEX(Fact_Expenses[CategoryName],COUNTA(Fact_Expenses[ExpenseID])-5),"") | G85: =IFERROR(INDEX(Fact_Expenses[Amount],COUNTA(Fact_Expenses[ExpenseID])-5),"")
A86: =Budget!A17 | B86: =Budget!F17 | D86: =IFERROR(INDEX(Fact_Expenses[Date],COUNTA(Fact_Expenses[ExpenseID])-6),"") | E86: =IFERROR(INDEX(Fact_Expenses[VendorName],COUNTA(Fact_Expenses[ExpenseID])-6),"") | F86: =IFERROR(INDEX(Fact_Expenses[CategoryName],COUNTA(Fact_Expenses[ExpenseID])-6),"") | G86: =IFERROR(INDEX(Fact_Expenses[Amount],COUNTA(Fact_Expenses[ExpenseID])-6),"")
A87: =Budget!A18 | B87: =Budget!F18 | D87: =IFERROR(INDEX(Fact_Expenses[Date],COUNTA(Fact_Expenses[ExpenseID])-7),"") | E87: =IFERROR(INDEX(Fact_Expenses[VendorName],COUNTA(Fact_Expenses[ExpenseID])-7),"") | F87: =IFERROR(INDEX(Fact_Expenses[CategoryName],COUNTA(Fact_Expenses[ExpenseID])-7),"") | G87: =IFERROR(INDEX(Fact_Expenses[Amount],COUNTA(Fact_Expenses[ExpenseID])-7),"")
A88: =Budget!A19 | B88: =Budget!F19
A89: =Budget!A20 | B89: =Budget!F20
A91: Cut-Back Analyzer
A92: Category | B92: Monthly Cost | C92: Annual Cost | D92: Potential Savings | E92: Priority | F92: Recommendation
A93: Dining & Entertainment | B93: =SUMIFS(Fact_Expenses[Amount],Fact_Expenses[CategoryName],"Dining & Entertainment",Fact_Expenses[Date],">="&EOMONTH(TodayDate,-2)+1,Fact_Expenses[Date],"<="&EOMONTH(TodayDate,-1))+SUMIFS(BankImportRaw[AbsAmount],BankImportRaw[CategoryName],"Dining & Entertainment",BankImportRaw[TransactionType],"Expense",BankImportRaw[Date],">="&EOMONTH(TodayDate,-2)+1,BankImportRaw[Date],"<="&EOMONTH(TodayDate,-1)) | C93: =B93*12 | D93: =C93*0.3 | E93: =RANK(D93,$D$93:$D$96) | F93: =IF(D93>500,"High-impact — consider cutting significantly",IF(D93>150,"Moderate — trim where possible","Low-impact — monitor only"))
A94: Shopping | B94: =SUMIFS(Fact_Expenses[Amount],Fact_Expenses[CategoryName],"Shopping",Fact_Expenses[Date],">="&EOMONTH(TodayDate,-2)+1,Fact_Expenses[Date],"<="&EOMONTH(TodayDate,-1))+SUMIFS(BankImportRaw[AbsAmount],BankImportRaw[CategoryName],"Shopping",BankImportRaw[TransactionType],"Expense",BankImportRaw[Date],">="&EOMONTH(TodayDate,-2)+1,BankImportRaw[Date],"<="&EOMONTH(TodayDate,-1)) | C94: =B94*12 | D94: =C94*0.3 | E94: =RANK(D94,$D$93:$D$96) | F94: =IF(D94>500,"High-impact — consider cutting significantly",IF(D94>150,"Moderate — trim where possible","Low-impact — monitor only"))
A95: Personal Care | B95: =SUMIFS(Fact_Expenses[Amount],Fact_Expenses[CategoryName],"Personal Care",Fact_Expenses[Date],">="&EOMONTH(TodayDate,-2)+1,Fact_Expenses[Date],"<="&EOMONTH(TodayDate,-1))+SUMIFS(BankImportRaw[AbsAmount],BankImportRaw[CategoryName],"Personal Care",BankImportRaw[TransactionType],"Expense",BankImportRaw[Date],">="&EOMONTH(TodayDate,-2)+1,BankImportRaw[Date],"<="&EOMONTH(TodayDate,-1)) | C95: =B95*12 | D95: =C95*0.3 | E95: =RANK(D95,$D$93:$D$96) | F95: =IF(D95>500,"High-impact — consider cutting significantly",IF(D95>150,"Moderate — trim where possible","Low-impact — monitor only"))
A96: Non-Essential Wants (all categories) | B96: =SUMIFS(Fact_Expenses[Amount],Fact_Expenses[NeedWantFlag],"Want",Fact_Expenses[Date],">="&EOMONTH(TodayDate,-2)+1,Fact_Expenses[Date],"<="&EOMONTH(TodayDate,-1))+SUMIFS(BankImportRaw[AbsAmount],BankImportRaw[NeedWantFlag],"Want",BankImportRaw[TransactionType],"Expense",BankImportRaw[Date],">="&EOMONTH(TodayDate,-2)+1,BankImportRaw[Date],"<="&EOMONTH(TodayDate,-1)) | C96: =B96*12 | D96: =C96*0.3 | E96: =RANK(D96,$D$93:$D$96) | F96: =IF(D96>500,"High-impact — consider cutting significantly",IF(D96>150,"Moderate — trim where possible","Low-impact — monitor only"))

Sheet Data Entry
A1: Data Entry
B4: Personal Finance Planner — Quick Start
B5: 1. Got a bank/credit-card CSV export? Go to the Bank Import tab first — paste it there, pick a Vendor per row, and it auto-suggests the Category and splits Expense vs Income for you.
B6: 2. Otherwise, enter transactions directly: Income for paychecks, Expenses for purchases, Savings for transfers toward a goal.
B7: 3. Use the dropdowns for Vendor / Category / Account / Payment Method — never type free text — so every report stays consistent.
B8: 4. Set your monthly budget per category on the Budget tab.
B9: 5. Press Ctrl+Alt+F9 (Formulas > Calculate Now) so every KPI, chart, and report recalculates.
B10: 6. Open the Dashboard tab to review updated KPIs, charts, and the Cut-Back Analyzer.
B12: Jump to a tab
B13: Bank Import | C13: Paste a bank/credit-card CSV export here first
B14: Income | C14: Log paychecks
B15: Expenses | C15: Log every purchase — the most-used tab
B16: Savings | C16: Set goals and log transfers toward them
B17: Budget | C17: Set your monthly budget per category
B18: Categories | C18: Add a new expense/income category
B19: Vendors | C19: Add a new vendor
B20: Accounts | C20: Add a new bank/credit account
B23: Adding new categories, vendors, or accounts
B24: New category: add a row to Dim_Category on the Categories tab. It appears in every dropdown and report automatically — no formulas anywhere else need to change.
B25: New vendor: add a row to Dim_Vendor on the Vendors tab, with its default category.
B26: New account: add a row to Dim_Account on the Accounts tab, with its starting Balance.
B27: All dropdowns use structured references (e.g. =Dim_Category[CategoryName]), which automatically grow to include new rows — not a fixed cell range — so nothing else needs to be touched.
B29: Where your data lives
B30: Everything is stored inside this workbook — the Excel Tables on each tab (Fact_Income, Fact_Expenses, Fact_SavingsTransfers, Dim_Category, Dim_Vendor, Dim_Account, Dim_Goal, Budget) ARE the database. There is no external server, cloud account, or database connection involved. That means: (1) this file is the only copy of your data — back it up (save a copy, or keep it in a synced folder / version control) the same way you would any important document; (2) if you keep this file in a git repo for versioning, remember that committing it puts your real transaction data into that repo's history — use a private repo if the numbers are real.

Sheet Bank Import
A1: Bank Import
A4: HOW TO USE THIS TAB
A5: 1. Export a CSV of transactions from your bank or credit card's website (usually Accounts > Download/Export).
A6: 2. Open that CSV, copy its Date / Description / Amount columns, and paste them into columns A, B, C of the table below — into the first blank row, not over existing rows — paste values only (Home > Paste > Values) so formatting doesn't fight the table.
A7: 3. Set 'Sign Convention' below to match how your export shows amounts (see the dropdown note).
A8: 4. Column D (Vendor) tries to auto-fill itself from any earlier row in this tab with the exact same bank description — if it's blank (new or slightly different wording), pick a Vendor from the dropdown. Category (E) then auto-fills from that vendor's default category; override it if needed.
A9: That's it — every row here counts immediately in the Dashboard KPIs, charts, Budget, and Vendor totals. There's no copy step: this tab IS the ledger for bank-derived transactions, the same way Expenses/Income are the ledger for anything you enter by hand. Don't delete rows after importing — deleting a row removes that transaction from every report.
A10: Note: the auto-fill in step 4 only recognizes an EXACT repeat of a description string. Recurring bills and subscriptions usually post with identical text every time, so those learn fast. If your bank appends a unique date or reference number to every line, matching won't catch it — you'll just pick the vendor again, same as the first time.
A11: Note: the Dashboard's 'Top Expenses' and 'Recent Transactions' widgets only look at the Expenses tab (a limitation of ranking individual transactions across two separate tables) — everything else (KPIs, Budget, Vendor totals, charts, Cut-Back Analyzer) includes this tab.
A13: Sign Convention for this import: | D13: Negative = Expense | E13: Most bank/debit exports show purchases as negative numbers (“Negative = Expense”). Most credit-card exports show charges as positive numbers and payments as negative (“Positive = Expense”). Check one real row against your bank statement to confirm.
A15: Paste your CSV's Date / Description / Amount into columns A-C — Vendor (D) auto-fills from earlier rows when it recognizes the description
A16: Date | B16: Description | C16: Amount | D16: VendorName | E16: CategoryName | F16: AccountName | G16: PaymentMethod | H16: TransactionType | I16: AbsAmount | J16: NeedWantFlag | K16: Notes
D17: ="" | E17: =IFERROR(INDEX(Dim_Category[CategoryName],MATCH(INDEX(Dim_Vendor[DefaultCategoryID],MATCH($D17,Dim_Vendor[VendorName],0)),Dim_Category[CategoryID],0)),"") | H17: =IF($C17="","",IF(SignConvention="Negative = Expense",IF($C17<0,"Expense","Income"),IF($C17>0,"Expense","Income"))) | I17: =IF($C17="","",ABS($C17))
D18: =IF($B18="","",IFERROR(INDEX($D$17:$D$17,MATCH($B18,$B$17:$B$17,0)),"")) | E18: =IFERROR(INDEX(Dim_Category[CategoryName],MATCH(INDEX(Dim_Vendor[DefaultCategoryID],MATCH($D18,Dim_Vendor[VendorName],0)),Dim_Category[CategoryID],0)),"") | H18: =IF($C18="","",IF(SignConvention="Negative = Expense",IF($C18<0,"Expense","Income"),IF($C18>0,"Expense","Income"))) | I18: =IF($C18="","",ABS($C18))
D19: =IF($B19="","",IFERROR(INDEX($D$17:$D$18,MATCH($B19,$B$17:$B$18,0)),"")) | E19: =IFERROR(INDEX(Dim_Category[CategoryName],MATCH(INDEX(Dim_Vendor[DefaultCategoryID],MATCH($D19,Dim_Vendor[VendorName],0)),Dim_Category[CategoryID],0)),"") | H19: =IF($C19="","",IF(SignConvention="Negative = Expense",IF($C19<0,"Expense","Income"),IF($C19>0,"Expense","Income"))) | I19: =IF($C19="","",ABS($C19))
D20: =IF($B20="","",IFERROR(INDEX($D$17:$D$19,MATCH($B20,$B$17:$B$19,0)),"")) | E20: =IFERROR(INDEX(Dim_Category[CategoryName],MATCH(INDEX(Dim_Vendor[DefaultCategoryID],MATCH($D20,Dim_Vendor[VendorName],0)),Dim_Category[CategoryID],0)),"") | H20: =IF($C20="","",IF(SignConvention="Negative = Expense",IF($C20<0,"Expense","Income"),IF($C20>0,"Expense","Income"))) | I20: =IF($C20="","",ABS($C20))
D21: =IF($B21="","",IFERROR(INDEX($D$17:$D$20,MATCH($B21,$B$17:$B$20,0)),"")) | E21: =IFERROR(INDEX(Dim_Category[CategoryName],MATCH(INDEX(Dim_Vendor[DefaultCategoryID],MATCH($D21,Dim_Vendor[VendorName],0)),Dim_Category[CategoryID],0)),"") | H21: =IF($C21="","",IF(SignConvention="Negative = Expense",IF($C21<0,"Expense","Income"),IF($C21>0,"Expense","Income"))) | I21: =IF($C21="","",ABS($C21))
D22: =IF($B22="","",IFERROR(INDEX($D$17:$D$21,MATCH($B22,$B$17:$B$21,0)),"")) | E22: =IFERROR(INDEX(Dim_Category[CategoryName],MATCH(INDEX(Dim_Vendor[DefaultCategoryID],MATCH($D22,Dim_Vendor[VendorName],0)),Dim_Category[CategoryID],0)),"") | H22: =IF($C22="","",IF(SignConvention="Negative = Expense",IF($C22<0,"Expense","Income"),IF($C22>0,"Expense","Income"))) | I22: =IF($C22="","",ABS($C22))
D23: =IF($B23="","",IFERROR(INDEX($D$17:$D$22,MATCH($B23,$B$17:$B$22,0)),"")) | E23: =IFERROR(INDEX(Dim_Category[CategoryName],MATCH(INDEX(Dim_Vendor[DefaultCategoryID],MATCH($D23,Dim_Vendor[VendorName],0)),Dim_Category[CategoryID],0)),"") | H23: =IF($C23="","",IF(SignConvention="Negative = Expense",IF($C23<0,"Expense","Income"),IF($C23>0,"Expense","Income"))) | I23: =IF($C23="","",ABS($C23))
D24: =IF($B24="","",IFERROR(INDEX($D$17:$D$23,MATCH($B24,$B$17:$B$23,0)),"")) | E24: =IFERROR(INDEX(Dim_Category[CategoryName],MATCH(INDEX(Dim_Vendor[DefaultCategoryID],MATCH($D24,Dim_Vendor[VendorName],0)),Dim_Category[CategoryID],0)),"") | H24: =IF($C24="","",IF(SignConvention="Negative = Expense",IF($C24<0,"Expense","Income"),IF($C24>0,"Expense","Income"))) | I24: =IF($C24="","",ABS($C24))
D25: =IF($B25="","",IFERROR(INDEX($D$17:$D$24,MATCH($B25,$B$17:$B$24,0)),"")) | E25: =IFERROR(INDEX(Dim_Category[CategoryName],MATCH(INDEX(Dim_Vendor[DefaultCategoryID],MATCH($D25,Dim_Vendor[VendorName],0)),Dim_Category[CategoryID],0)),"") | H25: =IF($C25="","",IF(SignConvention="Negative = Expense",IF($C25<0,"Expense","Income"),IF($C25>0,"Expense","Income"))) | I25: =IF($C25="","",ABS($C25))
D26: =IF($B26="","",IFERROR(INDEX($D$17:$D$25,MATCH($B26,$B$17:$B$25,0)),"")) | E26: =IFERROR(INDEX(Dim_Category[CategoryName],MATCH(INDEX(Dim_Vendor[DefaultCategoryID],MATCH($D26,Dim_Vendor[VendorName],0)),Dim_Category[CategoryID],0)),"") | H26: =IF($C26="","",IF(SignConvention="Negative = Expense",IF($C26<0,"Expense","Income"),IF($C26>0,"Expense","Income"))) | I26: =IF($C26="","",ABS($C26))
D27: =IF($B27="","",IFERROR(INDEX($D$17:$D$26,MATCH($B27,$B$17:$B$26,0)),"")) | E27: =IFERROR(INDEX(Dim_Category[CategoryName],MATCH(INDEX(Dim_Vendor[DefaultCategoryID],MATCH($D27,Dim_Vendor[VendorName],0)),Dim_Category[CategoryID],0)),"") | H27: =IF($C27="","",IF(SignConvention="Negative = Expense",IF($C27<0,"Expense","Income"),IF($C27>0,"Expense","Income"))) | I27: =IF($C27="","",ABS($C27))
D28: =IF($B28="","",IFERROR(INDEX($D$17:$D$27,MATCH($B28,$B$17:$B$27,0)),"")) | E28: =IFERROR(INDEX(Dim_Category[CategoryName],MATCH(INDEX(Dim_Vendor[DefaultCategoryID],MATCH($D28,Dim_Vendor[VendorName],0)),Dim_Category[CategoryID],0)),"") | H28: =IF($C28="","",IF(SignConvention="Negative = Expense",IF($C28<0,"Expense","Income"),IF($C28>0,"Expense","Income"))) | I28: =IF($C28="","",ABS($C28))
D29: =IF($B29="","",IFERROR(INDEX($D$17:$D$28,MATCH($B29,$B$17:$B$28,0)),"")) | E29: =IFERROR(INDEX(Dim_Category[CategoryName],MATCH(INDEX(Dim_Vendor[DefaultCategoryID],MATCH($D29,Dim_Vendor[VendorName],0)),Dim_Category[CategoryID],0)),"") | H29: =IF($C29="","",IF(SignConvention="Negative = Expense",IF($C29<0,"Expense","Income"),IF($C29>0,"Expense","Income"))) | I29: =IF($C29="","",ABS($C29))
D30: =IF($B30="","",IFERROR(INDEX($D$17:$D$29,MATCH($B30,$B$17:$B$29,0)),"")) | E30: =IFERROR(INDEX(Dim_Category[CategoryName],MATCH(INDEX(Dim_Vendor[DefaultCategoryID],MATCH($D30,Dim_Vendor[VendorName],0)),Dim_Category[CategoryID],0)),"") | H30: =IF($C30="","",IF(SignConvention="Negative = Expense",IF($C30<0,"Expense","Income"),IF($C30>0,"Expense","Income"))) | I30: =IF($C30="","",ABS($C30))
D31: =IF($B31="","",IFERROR(INDEX($D$17:$D$30,MATCH($B31,$B$17:$B$30,0)),"")) | E31: =IFERROR(INDEX(Dim_Category[CategoryName],MATCH(INDEX(Dim_Vendor[DefaultCategoryID],MATCH($D31,Dim_Vendor[VendorName],0)),Dim_Category[CategoryID],0)),"") | H31: =IF($C31="","",IF(SignConvention="Negative = Expense",IF($C31<0,"Expense","Income"),IF($C31>0,"Expense","Income"))) | I31: =IF($C31="","",ABS($C31))
D32: =IF($B32="","",IFERROR(INDEX($D$17:$D$31,MATCH($B32,$B$17:$B$31,0)),"")) | E32: =IFERROR(INDEX(Dim_Category[CategoryName],MATCH(INDEX(Dim_Vendor[DefaultCategoryID],MATCH($D32,Dim_Vendor[VendorName],0)),Dim_Category[CategoryID],0)),"") | H32: =IF($C32="","",IF(SignConvention="Negative = Expense",IF($C32<0,"Expense","Income"),IF($C32>0,"Expense","Income"))) | I32: =IF($C32="","",ABS($C32))
D33: =IF($B33="","",IFERROR(INDEX($D$17:$D$32,MATCH($B33,$B$17:$B$32,0)),"")) | E33: =IFERROR(INDEX(Dim_Category[CategoryName],MATCH(INDEX(Dim_Vendor[DefaultCategoryID],MATCH($D33,Dim_Vendor[VendorName],0)),Dim_Category[CategoryID],0)),"") | H33: =IF($C33="","",IF(SignConvention="Negative = Expense",IF($C33<0,"Expense","Income"),IF($C33>0,"Expense","Income"))) | I33: =IF($C33="","",ABS($C33))
D34: =IF($B34="","",IFERROR(INDEX($D$17:$D$33,MATCH($B34,$B$17:$B$33,0)),"")) | E34: =IFERROR(INDEX(Dim_Category[CategoryName],MATCH(INDEX(Dim_Vendor[DefaultCategoryID],MATCH($D34,Dim_Vendor[VendorName],0)),Dim_Category[CategoryID],0)),"") | H34: =IF($C34="","",IF(SignConvention="Negative = Expense",IF($C34<0,"Expense","Income"),IF($C34>0,"Expense","Income"))) | I34: =IF($C34="","",ABS($C34))
D35: =IF($B35="","",IFERROR(INDEX($D$17:$D$34,MATCH($B35,$B$17:$B$34,0)),"")) | E35: =IFERROR(INDEX(Dim_Category[CategoryName],MATCH(INDEX(Dim_Vendor[DefaultCategoryID],MATCH($D35,Dim_Vendor[VendorName],0)),Dim_Category[CategoryID],0)),"") | H35: =IF($C35="","",IF(SignConvention="Negative = Expense",IF($C35<0,"Expense","Income"),IF($C35>0,"Expense","Income"))) | I35: =IF($C35="","",ABS($C35))
D36: =IF($B36="","",IFERROR(INDEX($D$17:$D$35,MATCH($B36,$B$17:$B$35,0)),"")) | E36: =IFERROR(INDEX(Dim_Category[CategoryName],MATCH(INDEX(Dim_Vendor[DefaultCategoryID],MATCH($D36,Dim_Vendor[VendorName],0)),Dim_Category[CategoryID],0)),"") | H36: =IF($C36="","",IF(SignConvention="Negative = Expense",IF($C36<0,"Expense","Income"),IF($C36>0,"Expense","Income"))) | I36: =IF($C36="","",ABS($C36))
D37: =IF($B37="","",IFERROR(INDEX($D$17:$D$36,MATCH($B37,$B$17:$B$36,0)),"")) | E37: =IFERROR(INDEX(Dim_Category[CategoryName],MATCH(INDEX(Dim_Vendor[DefaultCategoryID],MATCH($D37,Dim_Vendor[VendorName],0)),Dim_Category[CategoryID],0)),"") | H37: =IF($C37="","",IF(SignConvention="Negative = Expense",IF($C37<0,"Expense","Income"),IF($C37>0,"Expense","Income"))) | I37: =IF($C37="","",ABS($C37))
D38: =IF($B38="","",IFERROR(INDEX($D$17:$D$37,MATCH($B38,$B$17:$B$37,0)),"")) | E38: =IFERROR(INDEX(Dim_Category[CategoryName],MATCH(INDEX(Dim_Vendor[DefaultCategoryID],MATCH($D38,Dim_Vendor[VendorName],0)),Dim_Category[CategoryID],0)),"") | H38: =IF($C38="","",IF(SignConvention="Negative = Expense",IF($C38<0,"Expense","Income"),IF($C38>0,"Expense","Income"))) | I38: =IF($C38="","",ABS($C38))
D39: =IF($B39="","",IFERROR(INDEX($D$17:$D$38,MATCH($B39,$B$17:$B$38,0)),"")) | E39: =IFERROR(INDEX(Dim_Category[CategoryName],MATCH(INDEX(Dim_Vendor[DefaultCategoryID],MATCH($D39,Dim_Vendor[VendorName],0)),Dim_Category[CategoryID],0)),"") | H39: =IF($C39="","",IF(SignConvention="Negative = Expense",IF($C39<0,"Expense","Income"),IF($C39>0,"Expense","Income"))) | I39: =IF($C39="","",ABS($C39))
D40: =IF($B40="","",IFERROR(INDEX($D$17:$D$39,MATCH($B40,$B$17:$B$39,0)),"")) | E40: =IFERROR(INDEX(Dim_Category[CategoryName],MATCH(INDEX(Dim_Vendor[DefaultCategoryID],MATCH($D40,Dim_Vendor[VendorName],0)),Dim_Category[CategoryID],0)),"") | H40: =IF($C40="","",IF(SignConvention="Negative = Expense",IF($C40<0,"Expense","Income"),IF($C40>0,"Expense","Income"))) | I40: =IF($C40="","",ABS($C40))
D41: =IF($B41="","",IFERROR(INDEX($D$17:$D$40,MATCH($B41,$B$17:$B$40,0)),"")) | E41: =IFERROR(INDEX(Dim_Category[CategoryName],MATCH(INDEX(Dim_Vendor[DefaultCategoryID],MATCH($D41,Dim_Vendor[VendorName],0)),Dim_Category[CategoryID],0)),"") | H41: =IF($C41="","",IF(SignConvention="Negative = Expense",IF($C41<0,"Expense","Income"),IF($C41>0,"Expense","Income"))) | I41: =IF($C41="","",ABS($C41))
D42: =IF($B42="","",IFERROR(INDEX($D$17:$D$41,MATCH($B42,$B$17:$B$41,0)),"")) | E42: =IFERROR(INDEX(Dim_Category[CategoryName],MATCH(INDEX(Dim_Vendor[DefaultCategoryID],MATCH($D42,Dim_Vendor[VendorName],0)),Dim_Category[CategoryID],0)),"") | H42: =IF($C42="","",IF(SignConvention="Negative = Expense",IF($C42<0,"Expense","Income"),IF($C42>0,"Expense","Income"))) | I42: =IF($C42="","",ABS($C42))
D43: =IF($B43="","",IFERROR(INDEX($D$17:$D$42,MATCH($B43,$B$17:$B$42,0)),"")) | E43: =IFERROR(INDEX(Dim_Category[CategoryName],MATCH(INDEX(Dim_Vendor[DefaultCategoryID],MATCH($D43,Dim_Vendor[VendorName],0)),Dim_Category[CategoryID],0)),"") | H43: =IF($C43="","",IF(SignConvention="Negative = Expense",IF($C43<0,"Expense","Income"),IF($C43>0,"Expense","Income"))) | I43: =IF($C43="","",ABS($C43))
D44: =IF($B44="","",IFERROR(INDEX($D$17:$D$43,MATCH($B44,$B$17:$B$43,0)),"")) | E44: =IFERROR(INDEX(Dim_Category[CategoryName],MATCH(INDEX(Dim_Vendor[DefaultCategoryID],MATCH($D44,Dim_Vendor[VendorName],0)),Dim_Category[CategoryID],0)),"") | H44: =IF($C44="","",IF(SignConvention="Negative = Expense",IF($C44<0,"Expense","Income"),IF($C44>0,"Expense","Income"))) | I44: =IF($C44="","",ABS($C44))
...

Sheet Income
A1: Income
A4: Dim_Source
A5: SourceID | B5: SourceName
A6: 1 | B6: Employer Payroll Inc
A7: 2 | B7: Other
A10: Fact_Income — enter each paycheck/deposit here. Dropdowns keep entries consistent; ID columns (hidden) auto-lookup for reporting.
A11: IncomeID | B11: Date | C11: SourceName | D11: SourceID | E11: CategoryName | F11: CategoryID | G11: AccountName | H11: AccountID | I11: GrossAmount | J11: TaxesWithheld | K11: NetAmount | L11: RecurringFlag | M11: Notes | N11: Description
A12: =ROW()-11 | B12: 45839 | C12: Employer Payroll Inc | D12: =IFERROR(INDEX(Dim_Source[SourceID],MATCH($C12,Dim_Source[SourceName],0)),"") | E12: Payroll | F12: =IFERROR(INDEX(Dim_Category[CategoryID],MATCH($E12,Dim_Category[CategoryName],0)),"") | G12: Checking | H12: =IFERROR(INDEX(Dim_Account[AccountID],MATCH($G12,Dim_Account[AccountName],0)),"") | I12: 5100 | J12: 1224 | K12: =$I12-$J12 | L12: Yes | M12: Semi-monthly payroll
A13: =ROW()-11 | B13: 45853 | C13: Employer Payroll Inc | D13: =IFERROR(INDEX(Dim_Source[SourceID],MATCH($C13,Dim_Source[SourceName],0)),"") | E13: Payroll | F13: =IFERROR(INDEX(Dim_Category[CategoryID],MATCH($E13,Dim_Category[CategoryName],0)),"") | G13: Checking | H13: =IFERROR(INDEX(Dim_Account[AccountID],MATCH($G13,Dim_Account[AccountName],0)),"") | I13: 5100 | J13: 1224 | K13: =$I13-$J13 | L13: Yes | M13: Semi-monthly payroll
A14: =ROW()-11 | B14: 45870 | C14: Employer Payroll Inc | D14: =IFERROR(INDEX(Dim_Source[SourceID],MATCH($C14,Dim_Source[SourceName],0)),"") | E14: Payroll | F14: =IFERROR(INDEX(Dim_Category[CategoryID],MATCH($E14,Dim_Category[CategoryName],0)),"") | G14: Checking | H14: =IFERROR(INDEX(Dim_Account[AccountID],MATCH($G14,Dim_Account[AccountName],0)),"") | I14: 5100 | J14: 1224 | K14: =$I14-$J14 | L14: Yes | M14: Semi-monthly payroll
A15: =ROW()-11 | B15: 45884 | C15: Employer Payroll Inc | D15: =IFERROR(INDEX(Dim_Source[SourceID],MATCH($C15,Dim_Source[SourceName],0)),"") | E15: Payroll | F15: =IFERROR(INDEX(Dim_Category[CategoryID],MATCH($E15,Dim_Category[CategoryName],0)),"") | G15: Checking | H15: =IFERROR(INDEX(Dim_Account[AccountID],MATCH($G15,Dim_Account[AccountName],0)),"") | I15: 5100 | J15: 1224 | K15: =$I15-$J15 | L15: Yes | M15: Semi-monthly payroll
A16: =ROW()-11 | B16: 45901 | C16: Employer Payroll Inc | D16: =IFERROR(INDEX(Dim_Source[SourceID],MATCH($C16,Dim_Source[SourceName],0)),"") | E16: Payroll | F16: =IFERROR(INDEX(Dim_Category[CategoryID],MATCH($E16,Dim_Category[CategoryName],0)),"") | G16: Checking | H16: =IFERROR(INDEX(Dim_Account[AccountID],MATCH($G16,Dim_Account[AccountName],0)),"") | I16: 5100 | J16: 1224 | K16: =$I16-$J16 | L16: Yes | M16: Semi-monthly payroll
A17: =ROW()-11 | B17: 45915 | C17: Employer Payroll Inc | D17: =IFERROR(INDEX(Dim_Source[SourceID],MATCH($C17,Dim_Source[SourceName],0)),"") | E17: Payroll | F17: =IFERROR(INDEX(Dim_Category[CategoryID],MATCH($E17,Dim_Category[CategoryName],0)),"") | G17: Checking | H17: =IFERROR(INDEX(Dim_Account[AccountID],MATCH($G17,Dim_Account[AccountName],0)),"") | I17: 5100 | J17: 1224 | K17: =$I17-$J17 | L17: Yes | M17: Semi-monthly payroll
A18: =ROW()-11 | B18: 45931 | C18: Employer Payroll Inc | D18: =IFERROR(INDEX(Dim_Source[SourceID],MATCH($C18,Dim_Source[SourceName],0)),"") | E18: Payroll | F18: =IFERROR(INDEX(Dim_Category[CategoryID],MATCH($E18,Dim_Category[CategoryName],0)),"") | G18: Checking | H18: =IFERROR(INDEX(Dim_Account[AccountID],MATCH($G18,Dim_Account[AccountName],0)),"") | I18: 5100 | J18: 1224 | K18: =$I18-$J18 | L18: Yes | M18: Semi-monthly payroll
A19: =ROW()-11 | B19: 45945 | C19: Employer Payroll Inc | D19: =IFERROR(INDEX(Dim_Source[SourceID],MATCH($C19,Dim_Source[SourceName],0)),"") | E19: Payroll | F19: =IFERROR(INDEX(Dim_Category[CategoryID],MATCH($E19,Dim_Category[CategoryName],0)),"") | G19: Checking | H19: =IFERROR(INDEX(Dim_Account[AccountID],MATCH($G19,Dim_Account[AccountName],0)),"") | I19: 5100 | J19: 1224 | K19: =$I19-$J19 | L19: Yes | M19: Semi-monthly payroll
A20: =ROW()-11 | B20: 45962 | C20: Employer Payroll Inc | D20: =IFERROR(INDEX(Dim_Source[SourceID],MATCH($C20,Dim_Source[SourceName],0)),"") | E20: Payroll | F20: =IFERROR(INDEX(Dim_Category[CategoryID],MATCH($E20,Dim_Category[CategoryName],0)),"") | G20: Checking | H20: =IFERROR(INDEX(Dim_Account[AccountID],MATCH($G20,Dim_Account[AccountName],0)),"") | I20: 5100 | J20: 1224 | K20: =$I20-$J20 | L20: Yes | M20: Semi-monthly payroll
A21: =ROW()-11 | B21: 45976 | C21: Employer Payroll Inc | D21: =IFERROR(INDEX(Dim_Source[SourceID],MATCH($C21,Dim_Source[SourceName],0)),"") | E21: Payroll | F21: =IFERROR(INDEX(Dim_Category[CategoryID],MATCH($E21,Dim_Category[CategoryName],0)),"") | G21: Checking | H21: =IFERROR(INDEX(Dim_Account[AccountID],MATCH($G21,Dim_Account[AccountName],0)),"") | I21: 5100 | J21: 1224 | K21: =$I21-$J21 | L21: Yes | M21: Semi-monthly payroll
A22: =ROW()-11 | B22: 45992 | C22: Employer Payroll Inc | D22: =IFERROR(INDEX(Dim_Source[SourceID],MATCH($C22,Dim_Source[SourceName],0)),"") | E22: Payroll | F22: =IFERROR(INDEX(Dim_Category[CategoryID],MATCH($E22,Dim_Category[CategoryName],0)),"") | G22: Checking | H22: =IFERROR(INDEX(Dim_Account[AccountID],MATCH($G22,Dim_Account[AccountName],0)),"") | I22: 5100 | J22: 1224 | K22: =$I22-$J22 | L22: Yes | M22: Semi-monthly payroll
A23: =ROW()-11 | B23: 46006 | C23: Employer Payroll Inc | D23: =IFERROR(INDEX(Dim_Source[SourceID],MATCH($C23,Dim_Source[SourceName],0)),"") | E23: Payroll | F23: =IFERROR(INDEX(Dim_Category[CategoryID],MATCH($E23,Dim_Category[CategoryName],0)),"") | G23: Checking | H23: =IFERROR(INDEX(Dim_Account[AccountID],MATCH($G23,Dim_Account[AccountName],0)),"") | I23: 5100 | J23: 1224 | K23: =$I23-$J23 | L23: Yes | M23: Semi-monthly payroll
... A37: =ROW()-11 | B37: 46218 | C37: Employer Payroll Inc | D37: =IFERROR(INDEX(Dim_Source[SourceID],MATCH($C37,Dim_Source[SourceName],0)),"") | E37: Payroll | F37: =IFERROR(INDEX(Dim_Category[CategoryID],MATCH($E37,Dim_Category[CategoryName],0)),"") | G37: Checking | H37: =IFERROR(INDEX(Dim_Account[AccountID],MATCH($G37,Dim_Account[AccountName],0)),"") | I37: 5100 | J37: 1224 | K37: =$I37-$J37 | L37: Yes | M37: Semi-monthly payroll

Sheet Expenses
A1: Expenses
A4: Fact_Expenses — every purchase goes here. Pick Vendor/Category/Account/Payment Method from dropdowns.
A5: ExpenseID | B5: Date | C5: VendorName | D5: VendorID | E5: CategoryName | F5: CategoryID | G5: AccountName | H5: AccountID | I5: PaymentMethod | J5: PaymentMethodID | K5: Amount | L5: NeedWantFlag | M5: RecurringFlag | N5: Notes | O5: Description | P5: CurMonthAmt
A6: =ROW()-5 | B6: 45872 | C6: Mortgage Lender | D6: =IFERROR(INDEX(Dim_Vendor[VendorID],MATCH($C6,Dim_Vendor[VendorName],0)),"") | E6: Mortgage | F6: =IFERROR(INDEX(Dim_Category[CategoryID],MATCH($E6,Dim_Category[CategoryName],0)),"") | G6: Checking | H6: =IFERROR(INDEX(Dim_Account[AccountID],MATCH($G6,Dim_Account[AccountName],0)),"") | I6: ACH | J6: =IFERROR(INDEX(Dim_PaymentMethod[PaymentMethodID],MATCH($I6,Dim_PaymentMethod[MethodName],0)),"") | K6: 2197.96 | L6: Need | M6: Yes | N6: Monthly mortgage payment | P6: =IF(AND($B6>=CurMonthStart,$B6<=CurMonthEnd),$K6,0)
A7: =ROW()-5 | B7: 45875 | C7: Whole Foods | D7: =IFERROR(INDEX(Dim_Vendor[VendorID],MATCH($C7,Dim_Vendor[VendorName],0)),"") | E7: Groceries | F7: =IFERROR(INDEX(Dim_Category[CategoryID],MATCH($E7,Dim_Category[CategoryName],0)),"") | G7: Credit Card | H7: =IFERROR(INDEX(Dim_Account[AccountID],MATCH($G7,Dim_Account[AccountName],0)),"") | I7: Credit Card | J7: =IFERROR(INDEX(Dim_PaymentMethod[PaymentMethodID],MATCH($I7,Dim_PaymentMethod[MethodName],0)),"") | K7: 172.25 | L7: Need | M7: No | P7: =IF(AND($B7>=CurMonthStart,$B7<=CurMonthEnd),$K7,0)
A8: =ROW()-5 | B8: 45878 | C8: Costco | D8: =IFERROR(INDEX(Dim_Vendor[VendorID],MATCH($C8,Dim_Vendor[VendorName],0)),"") | E8: Groceries | F8: =IFERROR(INDEX(Dim_Category[CategoryID],MATCH($E8,Dim_Category[CategoryName],0)),"") | G8: Credit Card | H8: =IFERROR(INDEX(Dim_Account[AccountID],MATCH($G8,Dim_Account[AccountName],0)),"") | I8: Credit Card | J8: =IFERROR(INDEX(Dim_PaymentMethod[PaymentMethodID],MATCH($I8,Dim_PaymentMethod[MethodName],0)),"") | K8: 236.28 | L8: Need | M8: No | N8: Bulk groceries | P8: =IF(AND($B8>=CurMonthStart,$B8<=CurMonthEnd),$K8,0)
A9: =ROW()-5 | B9: 45881 | C9: Shell Gas Station | D9: =IFERROR(INDEX(Dim_Vendor[VendorID],MATCH($C9,Dim_Vendor[VendorName],0)),"") | E9: Car | F9: =IFERROR(INDEX(Dim_Category[CategoryID],MATCH($E9,Dim_Category[CategoryName],0)),"") | G9: Credit Card | H9: =IFERROR(INDEX(Dim_Account[AccountID],MATCH($G9,Dim_Account[AccountName],0)),"") | I9: Credit Card | J9: =IFERROR(INDEX(Dim_PaymentMethod[PaymentMethodID],MATCH($I9,Dim_PaymentMethod[MethodName],0)),"") | K9: 49.98 | L9: Need | M9: No | N9: Gas | P9: =IF(AND($B9>=CurMonthStart,$B9<=CurMonthEnd),$K9,0)
A10: =ROW()-5 | B10: 45884 | C10: AutoZone | D10: =IFERROR(INDEX(Dim_Vendor[VendorID],MATCH($C10,Dim_Vendor[VendorName],0)),"") | E10: Car | F10: =IFERROR(INDEX(Dim_Category[CategoryID],MATCH($E10,Dim_Category[CategoryName],0)),"") | G10: Credit Card | H10: =IFERROR(INDEX(Dim_Account[AccountID],MATCH($G10,Dim_Account[AccountName],0)),"") | I10: Credit Card | J10: =IFERROR(INDEX(Dim_PaymentMethod[PaymentMethodID],MATCH($I10,Dim_PaymentMethod[MethodName],0)),"") | K10: 40.22 | L10: Need | M10: No | N10: Wiper blades / oil | P10: =IF(AND($B10>=CurMonthStart,$B10<=CurMonthEnd),$K10,0)
A11: =ROW()-5 | B11: 45887 | C11: City Electric Co | D11: =IFERROR(INDEX(Dim_Vendor[VendorID],MATCH($C11,Dim_Vendor[VendorName],0)),"") | E11: Utilities | F11: =IFERROR(INDEX(Dim_Category[CategoryID],MATCH($E11,Dim_Category[CategoryName],0)),"") | G11: Checking | H11: =IFERROR(INDEX(Dim_Account[AccountID],MATCH($G11,Dim_Account[AccountName],0)),"") | I11: ACH | J11: =IFERROR(INDEX(Dim_PaymentMethod[PaymentMethodID],MATCH($I11,Dim_PaymentMethod[MethodName],0)),"") | K11: 132.24 | L11: Need | M11: Yes | P11: =IF(AND($B11>=CurMonthStart,$B11<=CurMonthEnd),$K11,0)
A12: =ROW()-5 | B12: 45890 | C12: Comcast Xfinity | D12: =IFERROR(INDEX(Dim_Vendor[VendorID],MATCH($C12,Dim_Vendor[VendorName],0)),"") | E12: Utilities | F12: =IFERROR(INDEX(Dim_Category[CategoryID],MATCH($E12,Dim_Category[CategoryName],0)),"") | G12: Checking | H12: =IFERROR(INDEX(Dim_Account[AccountID],MATCH($G12,Dim_Account[AccountName],0)),"") | I12: ACH | J12: =IFERROR(INDEX(Dim_PaymentMethod[PaymentMethodID],MATCH($I12,Dim_PaymentMethod[MethodName],0)),"") | K12: 85.01 | L12: Need | M12: Yes | N12: Internet | P12: =IF(AND($B12>=CurMonthStart,$B12<=CurMonthEnd),$K12,0)
A13: =ROW()-5 | B13: 45893 | C13: Verizon Wireless | D13: =IFERROR(INDEX(Dim_Vendor[VendorID],MATCH($C13,Dim_Vendor[VendorName],0)),"") | E13: Utilities | F13: =IFERROR(INDEX(Dim_Category[CategoryID],MATCH($E13,Dim_Category[CategoryName],0)),"") | G13: Checking | H13: =IFERROR(INDEX(Dim_Account[AccountID],MATCH($G13,Dim_Account[AccountName],0)),"") | I13: ACH | J13: =IFERROR(INDEX(Dim_PaymentMethod[PaymentMethodID],MATCH($I13,Dim_PaymentMethod[MethodName],0)),"") | K13: 88.72 | L13: Need | M13: Yes | N13: Mobile phone | P13: =IF(AND($B13>=CurMonthStart,$B13<=CurMonthEnd),$K13,0)
A14: =ROW()-5 | B14: 45896 | C14: State Farm Insurance | D14: =IFERROR(INDEX(Dim_Vendor[VendorID],MATCH($C14,Dim_Vendor[VendorName],0)),"") | E14: Insurance | F14: =IFERROR(INDEX(Dim_Category[CategoryID],MATCH($E14,Dim_Category[CategoryName],0)),"") | G14: Checking | H14: =IFERROR(INDEX(Dim_Account[AccountID],MATCH($G14,Dim_Account[AccountName],0)),"") | I14: ACH | J14: =IFERROR(INDEX(Dim_PaymentMethod[PaymentMethodID],MATCH($I14,Dim_PaymentMethod[MethodName],0)),"") | K14: 140.23 | L14: Need | M14: Yes | N14: Auto + home insurance | P14: =IF(AND($B14>=CurMonthStart,$B14<=CurMonthEnd),$K14,0)
A15: =ROW()-5 | B15: 45872 | C15: Kaiser Permanente | D15: =IFERROR(INDEX(Dim_Vendor[VendorID],MATCH($C15,Dim_Vendor[VendorName],0)),"") | E15: Healthcare | F15: =IFERROR(INDEX(Dim_Category[CategoryID],MATCH($E15,Dim_Category[CategoryName],0)),"") | G15: Credit Card | H15: =IFERROR(INDEX(Dim_Account[AccountID],MATCH($G15,Dim_Account[AccountName],0)),"") | I15: Credit Card | J15: =IFERROR(INDEX(Dim_PaymentMethod[PaymentMethodID],MATCH($I15,Dim_PaymentMethod[MethodName],0)),"") | K15: 41.61 | L15: Need | M15: No | N15: Copay | P15: =IF(AND($B15>=CurMonthStart,$B15<=CurMonthEnd),$K15,0)
A16: =ROW()-5 | B16: 45875 | C16: Chipotle | D16: =IFERROR(INDEX(Dim_Vendor[VendorID],MATCH($C16,Dim_Vendor[VendorName],0)),"") | E16: Dining & Entertainment | F16: =IFERROR(INDEX(Dim_Category[CategoryID],MATCH($E16,Dim_Category[CategoryName],0)),"") | G16: Credit Card | H16: =IFERROR(INDEX(Dim_Account[AccountID],MATCH($G16,Dim_Account[AccountName],0)),"") | I16: Credit Card | J16: =IFERROR(INDEX(Dim_PaymentMethod[PaymentMethodID],MATCH($I16,Dim_PaymentMethod[MethodName],0)),"") | K16: 14.25 | L16: Want | M16: No | P16: =IF(AND($B16>=CurMonthStart,$B16<=CurMonthEnd),$K16,0)
A17: =ROW()-5 | B17: 45878 | C17: Netflix | D17: =IFERROR(INDEX(Dim_Vendor[VendorID],MATCH($C17,Dim_Vendor[VendorName],0)),"") | E17: Dining & Entertainment | F17: =IFERROR(INDEX(Dim_Category[CategoryID],MATCH($E17,Dim_Category[CategoryName],0)),"") | G17: Credit Card | H17: =IFERROR(INDEX(Dim_Account[AccountID],MATCH($G17,Dim_Account[AccountName],0)),"") | I17: Credit Card | J17: =IFERROR(INDEX(Dim_PaymentMethod[PaymentMethodID],MATCH($I17,Dim_PaymentMethod[MethodName],0)),"") | K17: 15.49 | L17: Want | M17: Yes | N17: Streaming subscription | P17: =IF(AND($B17>=CurMonthStart,$B17<=CurMonthEnd),$K17,0)
A18: =ROW()-5 | B18: 45881 | C18: AMC Theatres | D18: =IFERROR(INDEX(Dim_Vendor[VendorID],MATCH($C18,Dim_Vendor[VendorName],0)),"") | E18: Dining & Entertainment | F18: =IFERROR(INDEX(Dim_Category[CategoryID],MATCH($E18,Dim_Category[CategoryName],0)),"") | G18: Credit Card | H18: =IFERROR(INDEX(Dim_Account[AccountID],MATCH($G18,Dim_Account[AccountName],0)),"") | I18: Credit Card | J18: =IFERROR(INDEX(Dim_PaymentMethod[PaymentMethodID],MATCH($I18,Dim_PaymentMethod[MethodName],0)),"") | K18: 30.56 | L18: Want | M18: No | P18: =IF(AND($B18>=CurMonthStart,$B18<=CurMonthEnd),$K18,0)
A19: =ROW()-5 | B19: 45884 | C19: Planet Fitness | D19: =IFERROR(INDEX(Dim_Vendor[VendorID],MATCH($C19,Dim_Vendor[VendorName],0)),"") | E19: Personal Care | F19: =IFERROR(INDEX(Dim_Category[CategoryID],MATCH($E19,Dim_Category[CategoryName],0)),"") | G19: Checking | H19: =IFERROR(INDEX(Dim_Account[AccountID],MATCH($G19,Dim_Account[AccountName],0)),"") | I19: ACH | J19: =IFERROR(INDEX(Dim_PaymentMethod[PaymentMethodID],MATCH($I19,Dim_PaymentMethod[MethodName],0)),"") | K19: 25.01 | L19: Want | M19: Yes | N19: Gym membership | P19: =IF(AND($B19>=CurMonthStart,$B19<=CurMonthEnd),$K19,0)
A20: =ROW()-5 | B20: 45887 | C20: Amazon | D20: =IFERROR(INDEX(Dim_Vendor[VendorID],MATCH($C20,Dim_Vendor[VendorName],0)),"") | E20: Shopping | F20: =IFERROR(INDEX(Dim_Category[CategoryID],MATCH($E20,Dim_Category[CategoryName],0)),"") | G20: Credit Card | H20: =IFERROR(INDEX(Dim_Account[AccountID],MATCH($G20,Dim_Account[AccountName],0)),"") | I20: Credit Card | J20: =IFERROR(INDEX(Dim_PaymentMethod[PaymentMethodID],MATCH($I20,Dim_PaymentMethod[MethodName],0)),"") | K20: 63.28 | L20: Want | M20: No | P20: =IF(AND($B20>=CurMonthStart,$B20<=CurMonthEnd),$K20,0)
A21: =ROW()-5 | B21: 45890 | C21: Target | D21: =IFERROR(INDEX(Dim_Vendor[VendorID],MATCH($C21,Dim_Vendor[VendorName],0)),"") | E21: Shopping | F21: =IFERROR(INDEX(Dim_Category[CategoryID],MATCH($E21,Dim_Category[CategoryName],0)),"") | G21: Credit Card | H21: =IFERROR(INDEX(Dim_Account[AccountID],MATCH($G21,Dim_Account[AccountName],0)),"") | I21: Credit Card | J21: =IFERROR(INDEX(Dim_PaymentMethod[PaymentMethodID],MATCH($I21,Dim_PaymentMethod[MethodName],0)),"") | K21: 51.7 | L21: Want | M21: No | P21: =IF(AND($B21>=CurMonthStart,$B21<=CurMonthEnd),$K21,0)
A22: =ROW()-5 | B22: 45903 | C22: Mortgage Lender | D22: =IFERROR(INDEX(Dim_Vendor[VendorID],MATCH($C22,Dim_Vendor[VendorName],0)),"") | E22: Mortgage | F22: =IFERROR(INDEX(Dim_Category[CategoryID],MATCH($E22,Dim_Category[CategoryName],0)),"") | G22: Checking | H22: =IFERROR(INDEX(Dim_Account[AccountID],MATCH($G22,Dim_Account[AccountName],0)),"") | I22: ACH | J22: =IFERROR(INDEX(Dim_PaymentMethod[PaymentMethodID],MATCH($I22,Dim_PaymentMethod[MethodName],0)),"") | K22: 2201.56 | L22: Need | M22: Yes | N22: Monthly mortgage payment | P22: =IF(AND($B22>=CurMonthStart,$B22<=CurMonthEnd),$K22,0)
A23: =ROW()-5 | B23: 45906 | C23: Whole Foods | D23: =IFERROR(INDEX(Dim_Vendor[VendorID],MATCH($C23,Dim_Vendor[VendorName],0)),"") | E23: Groceries | F23: =IFERROR(INDEX(Dim_Category[CategoryID],MATCH($E23,Dim_Category[CategoryName],0)),"") | G23: Credit Card | H23: =IFERROR(INDEX(Dim_Account[AccountID],MATCH($G23,Dim_Account[AccountName],0)),"") | I23: Credit Card | J23: =IFERROR(INDEX(Dim_PaymentMethod[PaymentMethodID],MATCH($I23,Dim_PaymentMethod[MethodName],0)),"") | K23: 187.76 | L23: Need | M23: No | P23: =IF(AND($B23>=CurMonthStart,$B23<=CurMonthEnd),$K23,0)
A24: =ROW()-5 | B24: 45909 | C24: Costco | D24: =IFERROR(INDEX(Dim_Vendor[VendorID],MATCH($C24,Dim_Vendor[VendorName],0)),"") | E24: Groceries | F24: =IFERROR(INDEX(Dim_Category[CategoryID],MATCH($E24,Dim_Category[CategoryName],0)),"") | G24: Credit Card | H24: =IFERROR(INDEX(Dim_Account[AccountID],MATCH($G24,Dim_Account[AccountName],0)),"") | I24: Credit Card | J24: =IFERROR(INDEX(Dim_PaymentMethod[PaymentMethodID],MATCH($I24,Dim_PaymentMethod[MethodName],0)),"") | K24: 234.14 | L24: Need | M24: No | N24: Bulk groceries | P24: =IF(AND($B24>=CurMonthStart,$B24<=CurMonthEnd),$K24,0)
A25: =ROW()-5 | B25: 45912 | C25: Shell Gas Station | D25: =IFERROR(INDEX(Dim_Vendor[VendorID],MATCH($C25,Dim_Vendor[VendorName],0)),"") | E25: Car | F25: =IFERROR(INDEX(Dim_Category[CategoryID],MATCH($E25,Dim_Category[CategoryName],0)),"") | G25: Credit Card | H25: =IFERROR(INDEX(Dim_Account[AccountID],MATCH($G25,Dim_Account[AccountName],0)),"") | I25: Credit Card | J25: =IFERROR(INDEX(Dim_PaymentMethod[PaymentMethodID],MATCH($I25,Dim_PaymentMethod[MethodName],0)),"") | K25: 53.05 | L25: Need | M25: No | N25: Gas | P25: =IF(AND($B25>=CurMonthStart,$B25<=CurMonthEnd),$K25,0)
A26: =ROW()-5 | B26: 45915 | C26: AutoZone | D26: =IFERROR(INDEX(Dim_Vendor[VendorID],MATCH($C26,Dim_Vendor[VendorName],0)),"") | E26: Car | F26: =IFERROR(INDEX(Dim_Category[CategoryID],MATCH($E26,Dim_Category[CategoryName],0)),"") | G26: Credit Card | H26: =IFERROR(INDEX(Dim_Account[AccountID],MATCH($G26,Dim_Account[AccountName],0)),"") | I26: Credit Card | J26: =IFERROR(INDEX(Dim_PaymentMethod[PaymentMethodID],MATCH($I26,Dim_PaymentMethod[MethodName],0)),"") | K26: 40.67 | L26: Need | M26: No | N26: Wiper blades / oil | P26: =IF(AND($B26>=CurMonthStart,$B26<=CurMonthEnd),$K26,0)
A27: =ROW()-5 | B27: 45918 | C27: City Electric Co | D27: =IFERROR(INDEX(Dim_Vendor[VendorID],MATCH($C27,Dim_Vendor[VendorName],0)),"") | E27: Utilities | F27: =IFERROR(INDEX(Dim_Category[CategoryID],MATCH($E27,Dim_Category[CategoryName],0)),"") | G27: Checking | H27: =IFERROR(INDEX(Dim_Account[AccountID],MATCH($G27,Dim_Account[AccountName],0)),"") | I27: ACH | J27: =IFERROR(INDEX(Dim_PaymentMethod[PaymentMethodID],MATCH($I27,Dim_PaymentMethod[MethodName],0)),"") | K27: 118.45 | L27: Need | M27: Yes | P27: =IF(AND($B27>=CurMonthStart,$B27<=CurMonthEnd),$K27,0)
A28: =ROW()-5 | B28: 45921 | C28: Comcast Xfinity | D28: =IFERROR(INDEX(Dim_Vendor[VendorID],MATCH($C28,Dim_Vendor[VendorName],0)),"") | E28: Utilities | F28: =IFERROR(INDEX(Dim_Category[CategoryID],MATCH($E28,Dim_Category[CategoryName],0)),"") | G28: Checking | H28: =IFERROR(INDEX(Dim_Account[AccountID],MATCH($G28,Dim_Account[AccountName],0)),"") | I28: ACH | J28: =IFERROR(INDEX(Dim_PaymentMethod[PaymentMethodID],MATCH($I28,Dim_PaymentMethod[MethodName],0)),"") | K28: 83.9 | L28: Need | M28: Yes | N28: Internet | P28: =IF(AND($B28>=CurMonthStart,$B28<=CurMonthEnd),$K28,0)
A29: =ROW()-5 | B29: 45924 | C29: Verizon Wireless | D29: =IFERROR(INDEX(Dim_Vendor[VendorID],MATCH($C29,Dim_Vendor[VendorName],0)),"") | E29: Utilities | F29: =IFERROR(INDEX(Dim_Category[CategoryID],MATCH($E29,Dim_Category[CategoryName],0)),"") | G29: Checking | H29: =IFERROR(INDEX(Dim_Account[AccountID],MATCH($G29,Dim_Account[AccountName],0)),"") | I29: ACH | J29: =IFERROR(INDEX(Dim_PaymentMethod[PaymentMethodID],MATCH($I29,Dim_PaymentMethod[MethodName],0)),"") | K29: 98.01 | L29: Need | M29: Yes | N29: Mobile phone | P29: =IF(AND($B29>=CurMonthStart,$B29<=CurMonthEnd),$K29,0)
A30: =ROW()-5 | B30: 45927 | C30: State Farm Insurance | D30: =IFERROR(INDEX(Dim_Vendor[VendorID],MATCH($C30,Dim_Vendor[VendorName],0)),"") | E30: Insurance | F30: =IFERROR(INDEX(Dim_Category[CategoryID],MATCH($E30,Dim_Category[CategoryName],0)),"") | G30: Checking | H30: =IFERROR(INDEX(Dim_Account[AccountID],MATCH($G30,Dim_Account[AccountName],0)),"") | I30: ACH | J30: =IFERROR(INDEX(Dim_PaymentMethod[PaymentMethodID],MATCH($I30,Dim_PaymentMethod[MethodName],0)),"") | K30: 138.37 | L30: Need | M30: Yes | N30: Auto + home insurance | P30: =IF(AND($B30>=CurMonthStart,$B30<=CurMonthEnd),$K30,0)
A31: =ROW()-5 | B31: 45903 | C31: Kaiser Permanente | D31: =IFERROR(INDEX(Dim_Vendor[VendorID],MATCH($C31,Dim_Vendor[VendorName],0)),"") | E31: Healthcare | F31: =IFERROR(INDEX(Dim_Category[CategoryID],MATCH($E31,Dim_Category[CategoryName],0)),"") | G31: Credit Card | H31: =IFERROR(INDEX(Dim_Account[AccountID],MATCH($G31,Dim_Account[AccountName],0)),"") | I31: Credit Card | J31: =IFERROR(INDEX(Dim_PaymentMethod[PaymentMethodID],MATCH($I31,Dim_PaymentMethod[MethodName],0)),"") | K31: 42.52 | L31: Need | M31: No | N31: Copay | P31: =IF(AND($B31>=CurMonthStart,$B31<=CurMonthEnd),$K31,0)
A32: =ROW()-5 | B32: 45906 | C32: Chipotle | D32: =IFERROR(INDEX(Dim_Vendor[VendorID],MATCH($C32,Dim_Vendor[VendorName],0)),"") | E32: Dining & Entertainment | F32: =IFERROR(INDEX(Dim_Category[CategoryID],MATCH($E32,Dim_Category[CategoryName],0)),"") | G32: Credit Card | H32: =IFERROR(INDEX(Dim_Account[AccountID],MATCH($G32,Dim_Account[AccountName],0)),"") | I32: Credit Card | J32: =IFERROR(INDEX(Dim_PaymentMethod[PaymentMethodID],MATCH($I32,Dim_PaymentMethod[MethodName],0)),"") | K32: 14.25 | L32: Want | M32: No | P32: =IF(AND($B32>=CurMonthStart,$B32<=CurMonthEnd),$K32,0)
A33: =ROW()-5 | B33: 45909 | C33: Netflix | D33: =IFERROR(INDEX(Dim_Vendor[VendorID],MATCH($C33,Dim_Vendor[VendorName],0)),"") | E33: Dining & Entertainment | F33: =IFERROR(INDEX(Dim_Category[CategoryID],MATCH($E33,Dim_Category[CategoryName],0)),"") | G33: Credit Card | H33: =IFERROR(INDEX(Dim_Account[AccountID],MATCH($G33,Dim_Account[AccountName],0)),"") | I33: Credit Card | J33: =IFERROR(INDEX(Dim_PaymentMethod[PaymentMethodID],MATCH($I33,Dim_PaymentMethod[MethodName],0)),"") | K33: 15.49 | L33: Want | M33: Yes | N33: Streaming subscription | P33: =IF(AND($B33>=CurMonthStart,$B33<=CurMonthEnd),$K33,0)
A34: =ROW()-5 | B34: 45912 | C34: AMC Theatres | D34: =IFERROR(INDEX(Dim_Vendor[VendorID],MATCH($C34,Dim_Vendor[VendorName],0)),"") | E34: Dining & Entertainment | F34: =IFERROR(INDEX(Dim_Category[CategoryID],MATCH($E34,Dim_Category[CategoryName],0)),"") | G34: Credit Card | H34: =IFERROR(INDEX(Dim_Account[AccountID],MATCH($G34,Dim_Account[AccountName],0)),"") | I34: Credit Card | J34: =IFERROR(INDEX(Dim_PaymentMethod[PaymentMethodID],MATCH($I34,Dim_PaymentMethod[MethodName],0)),"") | K34: 34.34 | L34: Want | M34: No | P34: =IF(AND($B34>=CurMonthStart,$B34<=CurMonthEnd),$K34,0)
A35: =ROW()-5 | B35: 45915 | C35: Planet Fitness | D35: =IFERROR(INDEX(Dim_Vendor[VendorID],MATCH($C35,Dim_Vendor[VendorName],0)),"") | E35: Personal Care | F35: =IFERROR(INDEX(Dim_Category[CategoryID],MATCH($E35,Dim_Category[CategoryName],0)),"") | G35: Checking | H35: =IFERROR(INDEX(Dim_Account[AccountID],MATCH($G35,Dim_Account[AccountName],0)),"") | I35: ACH | J35: =IFERROR(INDEX(Dim_PaymentMethod[PaymentMethodID],MATCH($I35,Dim_PaymentMethod[MethodName],0)),"") | K35: 24.34 | L35: Want | M35: Yes | N35: Gym membership | P35: =IF(AND($B35>=CurMonthStart,$B35<=CurMonthEnd),$K35,0)
A36: =ROW()-5 | B36: 45918 | C36: Amazon | D36: =IFERROR(INDEX(Dim_Vendor[VendorID],MATCH($C36,Dim_Vendor[VendorName],0)),"") | E36: Shopping | F36: =IFERROR(INDEX(Dim_Category[CategoryID],MATCH($E36,Dim_Category[CategoryName],0)),"") | G36: Credit Card | H36: =IFERROR(INDEX(Dim_Account[AccountID],MATCH($G36,Dim_Account[AccountName],0)),"") | I36: Credit Card | J36: =IFERROR(INDEX(Dim_PaymentMethod[PaymentMethodID],MATCH($I36,Dim_PaymentMethod[MethodName],0)),"") | K36: 64.01 | L36: Want | M36: No | P36: =IF(AND($B36>=CurMonthStart,$B36<=CurMonthEnd),$K36,0)
A37: =ROW()-5 | B37: 45921 | C37: Target | D37: =IFERROR(INDEX(Dim_Vendor[VendorID],MATCH($C37,Dim_Vendor[VendorName],0)),"") | E37: Shopping | F37: =IFERROR(INDEX(Dim_Category[CategoryID],MATCH($E37,Dim_Category[CategoryName],0)),"") | G37: Credit Card | H37: =IFERROR(INDEX(Dim_Account[AccountID],MATCH($G37,Dim_Account[AccountName],0)),"") | I37: Credit Card | J37: =IFERROR(INDEX(Dim_PaymentMethod[PaymentMethodID],MATCH($I37,Dim_PaymentMethod[MethodName],0)),"") | K37: 50.81 | L37: Want | M37: No | P37: =IF(AND($B37>=CurMonthStart,$B37<=CurMonthEnd),$K37,0)
A38: =ROW()-5 | B38: 45933 | C38: Mortgage Lender | D38: =IFERROR(INDEX(Dim_Vendor[VendorID],MATCH($C38,Dim_Vendor[VendorName],0)),"") | E38: Mortgage | F38: =IFERROR(INDEX(Dim_Category[CategoryID],MATCH($E38,Dim_Category[CategoryName],0)),"") | G38: Checking | H38: =IFERROR(INDEX(Dim_Account[AccountID],MATCH($G38,Dim_Account[AccountName],0)),"") | I38: ACH | J38: =IFERROR(INDEX(Dim_PaymentMethod[PaymentMethodID],MATCH($I38,Dim_PaymentMethod[MethodName],0)),"") | K38: 2269.54 | L38: Need | M38: Yes | N38: Monthly mortgage payment | P38: =IF(AND($B38>=CurMonthStart,$B38<=CurMonthEnd),$K38,0)
A39: =ROW()-5 | B39: 45936 | C39: Whole Foods | D39: =IFERROR(INDEX(Dim_Vendor[VendorID],MATCH($C39,Dim_Vendor[VendorName],0)),"") | E39: Groceries | F39: =IFERROR(INDEX(Dim_Category[CategoryID],MATCH($E39,Dim_Category[CategoryName],0)),"") | G39: Credit Card | H39: =IFERROR(INDEX(Dim_Account[AccountID],MATCH($G39,Dim_Account[AccountName],0)),"") | I39: Credit Card | J39: =IFERROR(INDEX(Dim_PaymentMethod[PaymentMethodID],MATCH($I39,Dim_PaymentMethod[MethodName],0)),"") | K39: 189.51 | L39: Need | M39: No | P39: =IF(AND($B39>=CurMonthStart,$B39<=CurMonthEnd),$K39,0)
A40: =ROW()-5 | B40: 45939 | C40: Costco | D40: =IFERROR(INDEX(Dim_Vendor[VendorID],MATCH($C40,Dim_Vendor[VendorName],0)),"") | E40: Groceries | F40: =IFERROR(INDEX(Dim_Category[CategoryID],MATCH($E40,Dim_Category[CategoryName],0)),"") | G40: Credit Card | H40: =IFERROR(INDEX(Dim_Account[AccountID],MATCH($G40,Dim_Account[AccountName],0)),"") | I40: Credit Card | J40: =IFERROR(INDEX(Dim_PaymentMethod[PaymentMethodID],MATCH($I40,Dim_PaymentMethod[MethodName],0)),"") | K40: 257.14 | L40: Need | M40: No | N40: Bulk groceries | P40: =IF(AND($B40>=CurMonthStart,$B40<=CurMonthEnd),$K40,0)
A41: =ROW()-5 | B41: 45942 | C41: Shell Gas Station | D41: =IFERROR(INDEX(Dim_Vendor[VendorID],MATCH($C41,Dim_Vendor[VendorName],0)),"") | E41: Car | F41: =IFERROR(INDEX(Dim_Category[CategoryID],MATCH($E41,Dim_Category[CategoryName],0)),"") | G41: Credit Card | H41: =IFERROR(INDEX(Dim_Account[AccountID],MATCH($G41,Dim_Account[AccountName],0)),"") | I41: Credit Card | J41: =IFERROR(INDEX(Dim_PaymentMethod[PaymentMethodID],MATCH($I41,Dim_PaymentMethod[MethodName],0)),"") | K41: 54.22 | L41: Need | M41: No | N41: Gas | P41: =IF(AND($B41>=CurMonthStart,$B41<=CurMonthEnd),$K41,0)
A42: =ROW()-5 | B42: 45945 | C42: AutoZone | D42: =IFERROR(INDEX(Dim_Vendor[VendorID],MATCH($C42,Dim_Vendor[VendorName],0)),"") | E42: Car | F42: =IFERROR(INDEX(Dim_Category[CategoryID],MATCH($E42,Dim_Category[CategoryName],0)),"") | G42: Credit Card | H42: =IFERROR(INDEX(Dim_Account[AccountID],MATCH($G42,Dim_Account[AccountName],0)),"") | I42: Credit Card | J42: =IFERROR(INDEX(Dim_PaymentMethod[PaymentMethodID],MATCH($I42,Dim_PaymentMethod[MethodName],0)),"") | K42: 38.97 | L42: Need | M42: No | N42: Wiper blades / oil | P42: =IF(AND($B42>=CurMonthStart,$B42<=CurMonthEnd),$K42,0)
...

Sheet Savings
A1: Savings
A4: TOTAL SAVED (ALL GOALS) | D4: MONTHLY SAVINGS (THIS MONTH) | G4: SAVINGS RATE
A5: =SUM(Dim_Goal[CurrentAmount]) | D5: =SUMIFS(Fact_SavingsTransfers[Amount],Fact_SavingsTransfers[Date],">="&CurMonthStart,Fact_SavingsTransfers[Date],"<="&CurMonthEnd) | G5: =IFERROR(SUMIFS(Fact_SavingsTransfers[Amount],Fact_SavingsTransfers[Date],">="&CurMonthStart,Fact_SavingsTransfers[Date],"<="&CurMonthEnd)/SUMIFS(Fact_Income[NetAmount],Fact_Income[Date],">="&CurMonthStart,Fact_Income[Date],"<="&CurMonthEnd),0)
A9: Savings Goals — set a target; log transfers below to track progress automatically
A10: GoalID | B10: GoalName | C10: TargetAmount | D10: TargetDate | E10: Priority | F10: CurrentAmount | G10: Remaining | H10: Completion % | I10: Avg Monthly Contribution | J10: Projected Completion Date
A11: 1 | B11: Emergency Fund | C11: 25000 | D11: 46387 | E11: High | F11: =SUMIFS(Fact_SavingsTransfers[Amount],Fact_SavingsTransfers[GoalName],$B11) | G11: =MAX($C11-$F11,0) | H11: =MIN($F11/$C11,1) | I11: =IFERROR($F11/MAX(COUNTIFS(Fact_SavingsTransfers[GoalName],$B11),1),0) | J11: =IF($I11>0,TodayDate+($G11/$I11)*30,"N/A")
A12: 2 | B12: Vacation | C12: 6000 | D12: 46539 | E12: Medium | F12: =SUMIFS(Fact_SavingsTransfers[Amount],Fact_SavingsTransfers[GoalName],$B12) | G12: =MAX($C12-$F12,0) | H12: =MIN($F12/$C12,1) | I12: =IFERROR($F12/MAX(COUNTIFS(Fact_SavingsTransfers[GoalName],$B12),1),0) | J12: =IF($I12>0,TodayDate+($G12/$I12)*30,"N/A")
A13: 3 | B13: New Car | C13: 12000 | D13: 46752 | E13: Medium | F13: =SUMIFS(Fact_SavingsTransfers[Amount],Fact_SavingsTransfers[GoalName],$B13) | G13: =MAX($C13-$F13,0) | H13: =MIN($F13/$C13,1) | I13: =IFERROR($F13/MAX(COUNTIFS(Fact_SavingsTransfers[GoalName],$B13),1),0) | J13: =IF($I13>0,TodayDate+($G13/$I13)*30,"N/A")
A16: Fact_SavingsTransfers — log every deposit toward a goal
A17: TransferID | B17: Date | C17: GoalName | D17: GoalID | E17: AccountName | F17: AccountID | G17: Amount
A18: =ROW()-17 | B18: 45872 | C18: Emergency Fund | D18: =IFERROR(INDEX(Dim_Goal[GoalID],MATCH($C18,Dim_Goal[GoalName],0)),"") | E18: Savings | F18: =IFERROR(INDEX(Dim_Account[AccountID],MATCH($E18,Dim_Account[AccountName],0)),"") | G18: 500
A19: =ROW()-17 | B19: 45903 | C19: Emergency Fund | D19: =IFERROR(INDEX(Dim_Goal[GoalID],MATCH($C19,Dim_Goal[GoalName],0)),"") | E19: Savings | F19: =IFERROR(INDEX(Dim_Account[AccountID],MATCH($E19,Dim_Account[AccountName],0)),"") | G19: 500
A20: =ROW()-17 | B20: 45917 | C20: Vacation | D20: =IFERROR(INDEX(Dim_Goal[GoalID],MATCH($C20,Dim_Goal[GoalName],0)),"") | E20: Savings | F20: =IFERROR(INDEX(Dim_Account[AccountID],MATCH($E20,Dim_Account[AccountName],0)),"") | G20: 150
A21: =ROW()-17 | B21: 45933 | C21: Emergency Fund | D21: =IFERROR(INDEX(Dim_Goal[GoalID],MATCH($C21,Dim_Goal[GoalName],0)),"") | E21: Savings | F21: =IFERROR(INDEX(Dim_Account[AccountID],MATCH($E21,Dim_Account[AccountName],0)),"") | G21: 500
A22: =ROW()-17 | B22: 45950 | C22: New Car | D22: =IFERROR(INDEX(Dim_Goal[GoalID],MATCH($C22,Dim_Goal[GoalName],0)),"") | E22: Savings | F22: =IFERROR(INDEX(Dim_Account[AccountID],MATCH($E22,Dim_Account[AccountName],0)),"") | G22: 200
A23: =ROW()-17 | B23: 45964 | C23: Emergency Fund | D23: =IFERROR(INDEX(Dim_Goal[GoalID],MATCH($C23,Dim_Goal[GoalName],0)),"") | E23: Savings | F23: =IFERROR(INDEX(Dim_Account[AccountID],MATCH($E23,Dim_Account[AccountName],0)),"") | G23: 500
A24: =ROW()-17 | B24: 45978 | C24: Vacation | D24: =IFERROR(INDEX(Dim_Goal[GoalID],MATCH($C24,Dim_Goal[GoalName],0)),"") | E24: Savings | F24: =IFERROR(INDEX(Dim_Account[AccountID],MATCH($E24,Dim_Account[AccountName],0)),"") | G24: 150
A25: =ROW()-17 | B25: 45994 | C25: Emergency Fund | D25: =IFERROR(INDEX(Dim_Goal[GoalID],MATCH($C25,Dim_Goal[GoalName],0)),"") | E25: Savings | F25: =IFERROR(INDEX(Dim_Account[AccountID],MATCH($E25,Dim_Account[AccountName],0)),"") | G25: 500
A26: =ROW()-17 | B26: 46025 | C26: Emergency Fund | D26: =IFERROR(INDEX(Dim_Goal[GoalID],MATCH($C26,Dim_Goal[GoalName],0)),"") | E26: Savings | F26: =IFERROR(INDEX(Dim_Account[AccountID],MATCH($E26,Dim_Account[AccountName],0)),"") | G26: 500
A27: =ROW()-17 | B27: 46039 | C27: Vacation | D27: =IFERROR(INDEX(Dim_Goal[GoalID],MATCH($C27,Dim_Goal[GoalName],0)),"") | E27: Savings | F27: =IFERROR(INDEX(Dim_Account[AccountID],MATCH($E27,Dim_Account[AccountName],0)),"") | G27: 150
A28: =ROW()-17 | B28: 46042 | C28: New Car | D28: =IFERROR(INDEX(Dim_Goal[GoalID],MATCH($C28,Dim_Goal[GoalName],0)),"") | E28: Savings | F28: =IFERROR(INDEX(Dim_Account[AccountID],MATCH($E28,Dim_Account[AccountName],0)),"") | G28: 200
